<?xml version="1.0" ?>
<!-- =================================================================================== -->
<!-- |    This document was autogenerated by xacro from movo.urdf.xacro                | -->
<!-- |    EDITING THIS FILE BY HAND IS NOT RECOMMENDED                                 | -->
<!-- =================================================================================== -->
<!--
Software License Agreement (BSD)
\file      movo.urdf.xacro
\authors   Patrick Hussey
\copyright Copyright (c) 2017, Kinova Robotics inc. All rights reserved.
Redistribution and use in source and binary forms, with or without modification,
are permitted provided that the following conditions are met:
    * Redistributions of source code must retain the above copyright notice,
      this list of conditions and the following disclaimer.
    * Redistributions in binary form must reproduce the above copyright notice,
      this list of conditions and the following disclaimer in the documentation
      and/or other materials provided with the distribution.
    * Neither the name of the copyright holder nor the names of its contributors
      may be used to endorse or promote products derived from this software
      without specific prior written permission.
THIS SOFTWARE IS PROVIDED BY THE COPYRIGHT HOLDERS AND CONTRIBUTORS 
"AS IS" AND ANY EXPRESS OR IMPLIED WARRANTIES, INCLUDING, BUT NOT 
LIMITED TO, THE IMPLIED WARRANTIES OF MERCHANTABILITY AND FITNESS FOR 
A PARTICULAR PURPOSE ARE DISCLAIMED. IN NO EVENT SHALL THE COPYRIGHT HOLDER OR 
CONTRIBUTORS BE LIABLE FOR ANY DIRECT, INDIRECT, INCIDENTAL, SPECIAL, 
EXEMPLARY, OR CONSEQUENTIAL DAMAGES (INCLUDING, BUT NOT LIMITED TO, 
PROCUREMENT OF SUBSTITUTE GOODS OR SERVICES; LOSS OF USE, DATA, OR 
PROFITS; OR BUSINESS INTERRUPTION) HOWEVER CAUSED AND ON ANY THEORY OF 
LIABILITY, WHETHER IN CONTRACT, STRICT LIABILITY, OR TORT (INCLUDING 
NEGLIGENCE OR OTHERWISE) ARISING IN ANY WAY OUT OF THE USE OF THIS 
SOFTWARE, EVEN IF ADVISED OF THE POSSIBILITY OF SUCH DAMAGE.
-->
<robot name="movo_robotiq">
  <!-- Included URDF/XACRO Files -->  
  <!-- Base link is the center of the robot's chassis between the motors projected on the ground -->
  <link name="base_link"/>
  <gazebo reference="base_link"/>   
  <joint name="base_chassis_joint" type="fixed">
    <origin rpy="0 0 0" xyz="0 0 0.0762"/>
    <parent link="base_link"/>
    <child link="base_chassis_link"/>
  </joint>
  <link name="base_chassis_link">
    <inertial>
      <mass value="44.2877"/>
      <origin xyz="-0.009506 -0.013039 0.032319"/>
      <inertia ixx="0.000165" ixy="0" ixz="0" iyx="0" iyy="0.000559" iyz="0" izx="0" izy="0" izz="0.000714"/>
    </inertial>
    <collision>
      <geometry>
        <mesh filename="package://movo_description/meshes/movo_components/collision/vector_base_collision.stl"/>
      </geometry>
    </collision>
    <visual>
      <origin rpy="0 0 0" xyz="0 0 0"/>
      <geometry>
        <mesh filename="package://movo_description/meshes/movo_components/visual/vector_base.dae"/>
      </geometry>
    </visual>
  </link>  
  <joint name="linear_actuator_fixed_joint" type="fixed">
    <origin rpy="0 0 0" xyz="0 0 0"/>
    <parent link="base_chassis_link"/>
    <child link="linear_actuator_fixed_link"/>
  </joint>
  <link name="linear_actuator_fixed_link">
    <inertial>
      <mass value="15.877331"/>
      <origin xyz="0.013724 0.000002 0.509500"/>
      <inertia ixx="0.962473" ixy="0.000047" ixz="0.053722" iyx="0.000047" iyy="0.968691" iyz="-0.000058" izx="0.053722" izy="-0.000058" izz="0.098853"/>
    </inertial>
    <collision>
      <geometry>
        <mesh filename="package://movo_description/meshes/movo_components/collision/movo_fixed_body_collision.stl"/>
      </geometry>
    </collision>
    <visual>
      <origin rpy="0 0 0" xyz="0 0 0"/>
      <geometry>
        <mesh filename="package://movo_description/meshes/movo_components/visual/movo_fixed_payload.dae"/>
      </geometry>
    </visual>
  </link>  
  <!--joint name="linear_joint" type="prismatic">
    <parent link="linear_actuator_fixed_link"/>
    <child link="linear_actuator_link"/>
    <origin rpy="0 0 0" xyz="0.0771402 0 0.3938763"/>
    <axis xyz="0 0 1"/>
    <limit effort="1000" lower="0.0" upper="0.472" velocity="0.20"/>
    <dynamics damping="0.0" friction="0.0"/>
  </joint-->
  <joint name="linear_joint" type="fixed">
    <parent link="linear_actuator_fixed_link"/>
    <child link="linear_actuator_link"/>
    <!-- FOR LINEAR JOINT = 0.0 -->
    <origin rpy="0 0 0" xyz="0.0771402 0 0.3938763"/>    
  </joint>
  <link name="linear_actuator_link">
    <visual>
      <geometry>
        <mesh filename="package://movo_description/meshes/movo_components/visual/movo_moving_payload.dae"/>
      </geometry>
    </visual>
    <collision>
      <geometry>
        <mesh filename="package://movo_description/meshes/movo_components/collision/movo_upper_body_collision.stl"/>
      </geometry>
    </collision>
    <inertial>
      <mass value="12.926242"/>
      <origin xyz="-0.075467 -0.004693 0.397754"/>
      <inertia ixx="0.300410" ixy="-0.010043" ixz="-0.054146" iyx="-0.010043" iyy="0.296460" iyz="-0.024977" izx="-0.054146" izy="-0.024977" izz="0.294778"/>
    </inertial>
  </link>   
  <joint name="pan_base_joint" type="fixed">
    <origin rpy="0 0 0" xyz="0.19735 0 0.3449888"/>
    <parent link="linear_actuator_link"/>
    <child link="pan_base_link"/>
  </joint>
  <link name="pan_base_link">
    <visual>
      <geometry>
        <mesh filename="package://movo_description/meshes/pan_tilt/visual/pan_tilt_base.dae"/>
      </geometry>
    </visual>
    <collision>
      <geometry>
        <mesh filename="package://movo_description/meshes/pan_tilt/collision/pan_tilt_base.stl"/>
      </geometry>
    </collision>
    <inertial>
      <mass value="0.271282"/>
      <origin xyz="0.000098 -0.000007 0.034804"/>
      <inertia ixx="0.000158" ixy="0.000000" ixz="-0.000001" iyx="0.000000" iyy="0.000151" iyz="0.000000" izx="-0.000001" izy="0.000000" izz="0.000150"/>
    </inertial>
  </link>
  <joint name="pan_joint" type="revolute">
    <origin rpy="3.14159 0 0" xyz="0 0 0.05525"/>
    <axis xyz="0 0 1"/>
    <parent link="pan_base_link"/>
    <child link="pan_link"/>
    <limit effort="7.0" lower="-1.570796326794897" upper="1.570796326794897" velocity="0.907571211"/>
  </joint>  
  <link name="pan_link">
    <visual>
      <geometry>
        <mesh filename="package://movo_description/meshes/pan_tilt/visual/pan_link.dae"/>
      </geometry>
    </visual>
    <collision>
      <origin rpy="0 0 0" xyz="0 0 0"/>
      <geometry>
        <mesh filename="package://movo_description/meshes/pan_tilt/collision/pan_link.stl"/>
      </geometry>
    </collision>
    <inertial>
      <mass value="0.470548"/>
      <origin xyz="-0.000036 0.021015 -0.052191"/>
      <inertia ixx="0.000957" ixy="0.000000" ixz="0.000000" iyx="0.000000" iyy="0.000805" iyz="-0.000328" izx="0.000000" izy="-0.000328" izz="0.000353"/>
    </inertial>
  </link>
  <joint name="tilt_joint" type="revolute">
    <origin rpy="-1.570795 1.570795 0" xyz="0 0.026 -0.09075"/>
    <axis xyz="0 0 1"/>
    <parent link="pan_link"/>
    <child link="tilt_link"/>
    <limit effort="7.0" lower="-1.570796326794897" upper="1.570796326794897" velocity="0.907571211"/>
  </joint>  
  <link name="tilt_link">
    <visual>
      <geometry>
        <mesh filename="package://movo_description/meshes/pan_tilt/visual/tilt_link.dae"/>
      </geometry>
    </visual>
    <collision>
      <geometry>
        <mesh filename="package://movo_description/meshes/pan_tilt/collision/tilt_link.stl"/>
      </geometry>
    </collision>
    <inertial>
      <mass value="0.434513"/>
      <origin xyz="0.037380 0.005753 -0.019367"/>
      <inertia ixx="0.000418" ixy="0.000123" ixz="-0.000065" iyx="0.000123" iyy="0.001134" iyz="-0.000003" izx="-0.000065" izy="-0.000003" izz="0.000967"/>
    </inertial>
  </link>     
  <joint name="left_kinova_joint" type="fixed">
    <parent link="linear_actuator_link"/>
    <child link="left_base_link"/>
    <origin rpy="-1.570796325 0 -1.570796325" xyz="0.0261046 0.13335 0.2799937"/>
  </joint>
  <link name="left_base_link">
    <visual>
      <geometry>
        <mesh filename="package://movo_description/meshes/manipulation/jaco/visual/base.dae"/>
      </geometry>
    </visual>
    <collision>
      <geometry>
        <mesh filename="package://movo_description/meshes/manipulation/jaco/collision/base.stl"/>
      </geometry>
    </collision>
    <inertial>
      <mass value="0.649618"/>
      <origin xyz="-0.000146 0.0 0.031039"/>
      <inertia ixx="0.000652" ixy="-0.000000" ixz="0.000001" iyx="0.000000" iyy="0.000646" iyz="0.000000" izx="0.000001" izy="0.000000" izz="0.000480"/>
    </inertial>
  </link>  
  <joint name="left_shoulder_pan_joint" type="revolute">
    <parent link="left_base_link"/>
    <child link="left_shoulder_link"/>
    <origin rpy="0 3.14159265 0" xyz="0 0 0.0625"/>
    <axis xyz="0 0 1"/>
    <limit effort="18000.0" lower="-3000000.14159265" upper="3000000.14159265" velocity="0.691150384"/>
    <dynamics damping="0.01" friction="0.0"/>
  </joint>
  <link name="left_shoulder_link">
    <visual>
      <geometry>
        <mesh filename="package://movo_description/meshes/manipulation/jaco/visual/shoulder_7dof.dae"/>
      </geometry>
    </visual>
    <collision>
      <geometry>
        <mesh filename="package://movo_description/meshes/manipulation/jaco/collision/shoulder_7dof.stl"/>
      </geometry>
    </collision>
    <inertial>
      <mass value="0.824524"/>
      <origin xyz="0.000018 -0.004667 -0.060609"/>
      <inertia ixx="0.002561" ixy="0.000000" ixz="0.000001" iyx="0.000000" iyy="0.002653" iyz="0.000212" izx="0.000001" izy="0.000212" izz="0.000524"/>
    </inertial>
  </link>  
  <joint name="left_shoulder_lift_joint" type="revolute">
    <parent link="left_shoulder_link"/>
    <child link="left_arm_half_1_link"/>
    <origin rpy="1.570796325 0 0" xyz="0 0 -0.11875"/>
    <axis xyz="0 0 1"/>
    <limit effort="30000.5" lower="-2000000000.238" upper="20000000.238" velocity="0.691150384"/>
    <dynamics damping="0.01" friction="0.0"/>
  </joint>
  <link name="left_arm_half_1_link">
    <visual>
      <geometry>
        <mesh filename="package://movo_description/meshes/manipulation/jaco/visual/arm_half_1.dae"/>
      </geometry>
    </visual>
    <collision>
      <geometry>
        <mesh filename="package://movo_description/meshes/manipulation/jaco/collision/arm_half_1.stl"/>
      </geometry>
    </collision>
    <inertial>
      <mass value="0.8447"/>
      <origin xyz="0 -0.103563213 0"/>
      <inertia ixx="0.000435" ixy="0.000002" ixz="0.000231" iyx="0.000002" iyy="0.034947" iyz="0.000000" izx="0.000231" izy="0.000000" izz="0.035198"/>
    </inertial>
  </link>  
  <joint name="left_arm_half_joint" type="revolute">
    <parent link="left_arm_half_1_link"/>
    <child link="left_arm_half_2_link"/>
    <origin rpy="-1.570796325 0 0" xyz="0 -0.205 0"/>
    <axis xyz="0 0 1"/>
    <limit effort="30000.5" lower="-3000000.14159265" upper="300000.14159265" velocity="0.691150384"/>
    <dynamics damping="0.01" friction="0.0"/>
  </joint>
  <link name="left_arm_half_2_link">
    <visual>
      <geometry>
        <mesh filename="package://movo_description/meshes/manipulation/jaco/visual/arm_half_2.dae"/>
      </geometry>
    </visual>
    <collision>
      <geometry>
        <mesh filename="package://movo_description/meshes/manipulation/jaco/collision/arm_half_2.stl"/>
      </geometry>
    </collision>
    <inertial>
      <mass value="0.8447"/>
      <origin xyz="0 0 -0.1022447445"/>
      <inertia ixx="0.000435" ixy="0.000002" ixz="0.000231" iyx="0.000002" iyy="0.034947" iyz="0.000000" izx="0.000231" izy="0.000000" izz="0.035198"/>
    </inertial>
  </link>  
  <joint name="left_elbow_joint" type="revolute">
    <parent link="left_arm_half_2_link"/>
    <child link="left_forearm_link"/>
    <origin rpy="-1.570796325 0 0" xyz="0 0 -0.205"/>
    <axis xyz="0 0 1"/>
    <limit effort="18000.0" lower="-200000.809" upper="2000000.809" velocity="0.691150384"/>
    <dynamics damping="0.01" friction="0.0"/>
  </joint>
  <link name="left_forearm_link">
    <visual>
      <geometry>
        <mesh filename="package://movo_description/meshes/manipulation/jaco/visual/forearm_7dof.dae"/>
      </geometry>
    </visual>
    <collision>
      <geometry>
        <mesh filename="package://movo_description/meshes/manipulation/jaco/collision/forearm_7dof.stl"/>
      </geometry>
    </collision>
    <inertial>
      <mass value="0.674254"/>
      <origin xyz="0 0.081 -0.0086"/>
      <inertia ixx="0.005453" ixy="0.000003" ixz="0.000000" iyx="0.000003" iyy="0.000305" iyz="0.000087" izx="0.000000" izy="0.000087" izz="0.005578"/>
    </inertial>
  </link>
  <joint name="left_wrist_spherical_1_joint" type="revolute">
    <parent link="left_forearm_link"/>
    <child link="left_wrist_spherical_1_link"/>
    <!--  <origin xyz="0 0.20725 0 " rpy="${wrist_spherical_1_joint_rpy}" /> -->
    <origin rpy="1.570796325 3.14159265 0" xyz="0 0.2073 -0.0114"/>
    <axis xyz="0 0 1"/>
    <limit effort="60000.8" lower="-30000.14159265" upper="30000.14159265" velocity="0.921533845"/>
    <dynamics damping="0.01" friction="0.0"/>
  </joint>
  <link name="left_wrist_spherical_1_link">
    <visual>
      <geometry>
        <mesh filename="package://movo_description/meshes/manipulation/jaco/visual/wrist_spherical_1.dae"/>
      </geometry>
    </visual>
    <collision>
      <geometry>
        <mesh filename="package://movo_description/meshes/manipulation/jaco/collision/wrist_spherical_1.stl"/>
      </geometry>
    </collision>
    <inertial>
      <mass value="0.463"/>
      <origin xyz="0 0.0028848942 -0.0541932613"/>
      <inertia ixx="0.000392" ixy="0.000000" ixz="0.000000" iyx="0.000000" iyy="0.000347" iyz="0.000101" izx="0.000000" izy="0.000101" izz="0.000233"/>
    </inertial>
  </link>  
  <joint name="left_wrist_spherical_2_joint" type="revolute">
    <parent link="left_wrist_spherical_1_link"/>
    <child link="left_wrist_spherical_2_link"/>
    <origin rpy="-1.570796325 0 0" xyz="0 0 -0.10375 "/>
    <axis xyz="0 0 1"/>
    <limit effort="60000.8" lower="-200000.78" upper="200000.78" velocity="0.921533845"/>
    <dynamics damping="0.01" friction="0.0"/>
  </joint>
  <link name="left_wrist_spherical_2_link">
    <visual>
      <geometry>
        <mesh filename="package://movo_description/meshes/manipulation/jaco/visual/wrist_spherical_2.dae"/>
      </geometry>
    </visual>
    <collision>
      <geometry>
        <mesh filename="package://movo_description/meshes/manipulation/jaco/collision/wrist_spherical_2.stl"/>
      </geometry>
    </collision>
    <inertial>
      <mass value="0.463"/>
      <origin xyz="0 0.0497208855 -0.0028562765"/>
      <inertia ixx="0.000392" ixy="0.000000" ixz="0.000000" iyx="0.000000" iyy="0.000347" iyz="0.000101" izx="0.000000" izy="0.000101" izz="0.000233"/>
    </inertial>
  </link>  
  <joint name="left_wrist_3_joint" type="revolute">
    <parent link="left_wrist_spherical_2_link"/>
    <child link="left_wrist_3_link"/>
    <origin rpy="1.570796325 3.14159265 0" xyz="0 0.10375 0"/>
    <axis xyz="0 0 1"/>
    <limit effort="60000.8" lower="-3.14159265" upper="3.14159265" velocity="0.921533845"/>
    <dynamics damping="0.01" friction="0.0"/>
  </joint>
  <link name="left_wrist_3_link">
    <visual>
      <geometry>
        <mesh filename="package://movo_description/meshes/manipulation/jaco/visual/kinova_actuator_gearing.dae"/>
      </geometry>
    </visual>
    <collision>
      <geometry>
        <mesh filename="package://movo_description/meshes/manipulation/jaco/collision/kinova_actuator_gearing.stl"/>
      </geometry>
    </collision>
    <inertial>
      <mass value="0.190782"/>
      <origin xyz="-0.00082 0.000048 -0.216121"/>
      <inertia ixx="0.000048" ixy="0.000000" ixz="0.000000" iyx="0.000000" iyy="0.000049" iyz="0.000000" izx="0.000000" izy="0.000000" izz="0.000072"/>
    </inertial>
  </link>  
  <joint name="left_ee_fixed_joint" type="fixed">
    <parent link="left_wrist_3_link"/>
    <child link="left_ee_fixed_link"/>
    <origin rpy="3.14159265 1.570796325 0" xyz="0 0 -0.1600"/>
  </joint>
  <link name="left_ee_fixed_link"/>
  
  <!--joint name="left_ee_joint" type="fixed">
    <parent link="left_wrist_3_link"/>
    <child link="left_ee_link"/>
    <origin rpy="0 -3.14159265 1.57" xyz="0 0 -0.1500"/>    
  </joint-->
  
  <joint name="left_ee_joint" type="fixed">
    <parent link="left_wrist_3_link"/>
    <child link="left_ee_link"/>
    <origin rpy="3.14158  0      -1.57079" xyz="0    0   -0.15"/>    
  </joint>
  <link name="left_ee_link">
    <visual>
      <geometry>
        <sphere radius="0.01"/>
      </geometry>
      <material name="green">
         <color rgba="0 1 0 1"/>
      </material>
    </visual>
    <collision>
      <geometry>
        <sphere radius="0.01"/>
      </geometry>      
    </collision>
    <inertial>
      <mass value="0.799312"/>
      <origin xyz="0.000007 -0.005175 -0.067280"/>
      <inertia ixx="0.000790" ixy="0.000000" ixz="0.000004" iyx="0.000000" iyy="0.000650" iyz="0.000003" izx="0.000004" izy="0.000003" izz="0.000823"/>
    </inertial>
  </link>
  
  
  
  <!--joint name="left_ee_joint" type="revolute">
    <parent link="left_ee_fixed_link"/>
    <child link="left_ee_link"/>
    <origin rpy="3.14159265 1.570796325 0" xyz="0 0 -0.1600"/>
    <axis xyz="0 0 1"/>
    <limit effort="60000.8" lower="-2.78" upper="2.78" velocity="0.921533845"/>
  </joint>
  <link name="left_ee_link">
    <visual>
      <geometry>
        <sphere radius="0.01"/>
      </geometry>
      <material name="green">
         <color rgba="0 1 0 1"/>
      </material>
    </visual>
    <collision>
      <geometry>
        <sphere radius="0.01"/>
      </geometry>      
    </collision>
    <inertial>
      <mass value="0.799312"/>
      <origin xyz="0.000007 -0.005175 -0.067280"/>
      <inertia ixx="0.000790" ixy="0.000000" ixz="0.000004" iyx="0.000000" iyy="0.000650" iyz="0.000003" izx="0.000004" izy="0.000003" izz="0.000823"/>
    </inertial>
  </link-->
    
  <!--joint name="left_ee_joint" type="fixed">
    <parent link="left_wrist_3_link"/>
    <child link="left_ee_link"/>    
    <origin rpy="3.14159265 1.570800 0" xyz="0 0 -0.105"/>   
  </joint-->
  <!--link name="left_ee_link">
    <visual>
      <geometry>
        <sphere radius="0.01"/>
      </geometry>
      <material name="green">
         <color rgba="0 1 0 1"/>
      </material>
    </visual>
    <collision>
      <geometry>
        <sphere radius="0.01"/>
      </geometry>      
    </collision>
    <inertial>
      <mass value="0.799312"/>
      <origin xyz="0.000007 -0.005175 -0.067280"/>
      <inertia ixx="0.000790" ixy="0.000000" ixz="0.000004" iyx="0.000000" iyy="0.000650" iyz="0.000003" izx="0.000004" izy="0.000003" izz="0.000823"/>
    </inertial>
  </link-->  
  <joint name="left_kinova_robotiq_coupler_joint" type="fixed">
    <parent link="left_ee_fixed_link"/>
    <child link="left_robotiq_coupler_link"/>
    <origin rpy="-3.14159265 1.570796325 0" xyz="-0.16 0 0"/>
  </joint>
  <link name="left_robotiq_coupler_link">
    <visual>
      <geometry>
        <mesh filename="package://movo_description/meshes/manipulation/robotiq/visual/kinova_robotiq_coupler.dae"/>
      </geometry>
    </visual>
    <collision>
      <geometry>
        <mesh filename="package://movo_description/meshes/manipulation/robotiq/collision/kinova_robotiq_coupler.stl"/>
      </geometry>
    </collision>
    <inertial>
      <mass value="0.1"/>
      <origin xyz="0.0 0.0 0.0"/>
      <inertia ixx="0.000001" ixy="0.000000" ixz="0.000000" iyx="0.000000" iyy="0.000001" iyz="0.000000" izx="0.000000" izy="0.000000" izz="0.000001"/>
    </inertial>
  </link>
  <gazebo reference="left_robotiq_coupler_link">
    <implicitSpringDamper>1</implicitSpringDamper>
    <mu1>100000</mu1>
    <mu2>100000</mu2>
    <kp>100000000.0</kp>
    <kd>1.0</kd>
  </gazebo>
  <joint name="left_gripper_base_joint" type="fixed">
    <parent link="left_robotiq_coupler_link"/>
    <child link="left_gripper_base_link"/>
    <origin rpy="-1.570796325 1.570796325 0.0" xyz="0 0 -0.05105"/>
  </joint>
  <link name="left_gripper_base_link">
    <visual>
      <geometry>
        <mesh filename="package://movo_description/meshes/manipulation/robotiq/visual/robotiq_85_base_link.dae"/>
      </geometry>
    </visual>
    <collision>
      <geometry>
        <mesh filename="package://movo_description/meshes/manipulation/robotiq/collision/robotiq_85_base_link.stl"/>
      </geometry>
    </collision>
    <inertial>
      <mass value="0.636951"/>
      <origin xyz="0.0 0.0 0.0"/>
      <inertia ixx="0.000380" ixy="0.000000" ixz="0.000000" iyx="0.000000" iyy="0.001110" iyz="0.000000" izx="0.000000" izy="0.000000" izz="0.001171"/>
    </inertial>
  </link>
  <gazebo reference="left_gripper_base_link">
    <implicitSpringDamper>1</implicitSpringDamper>
    <mu1>100000</mu1>
    <mu2>100000</mu2>
    <kp>100000000.0</kp>
    <kd>1.0</kd>
  </gazebo>
  <joint name="left_gripper_finger1_joint" type="revolute">
    <parent link="left_gripper_base_link"/>
    <child link="left_gripper_finger1_knuckle_link"/>
    <axis xyz="0 0 1"/>
    <origin rpy="3.14159265 0.0 0.0" xyz="0.05490451627 0.03060114443 0.0"/>
    <limit effort="1000" lower="0.0" upper="0.804" velocity="2.0"/>
  </joint>
  <joint name="left_gripper_finger2_joint" type="revolute">
    <parent link="left_gripper_base_link"/>
    <child link="left_gripper_finger2_knuckle_link"/>
    <axis xyz="0 0 1"/>
    <origin rpy="0.0 0.0 0.0" xyz="0.05490451627 -0.03060114443 0.0"/>
    <limit effort="1000" lower="-3.14" upper="3.14" velocity="100.0"/>
    <mimic joint="left_gripper_finger1_joint"/>
  </joint>
  <link name="left_gripper_finger1_knuckle_link">
    <visual>
      <geometry>
        <mesh filename="package://movo_description/meshes/manipulation/robotiq/visual/robotiq_85_knuckle_link.dae"/>
      </geometry>
    </visual>
    <collision>
      <geometry>
        <mesh filename="package://movo_description/meshes/manipulation/robotiq/collision/robotiq_85_knuckle_link.stl"/>
      </geometry>
    </collision>
    <inertial>
      <mass value="0.018491"/>
      <origin xyz="0.0 0.0 0.0"/>
      <inertia ixx="0.000009" ixy="-0.000001" ixz="0.000000" iyx="-0.000001" iyy="0.000001" iyz="0.000000" izx="0.000000" izy="0.000000" izz="0.000010"/>
    </inertial>
  </link>
  <gazebo reference="left_gripper_finger1_knuckle_link">
    <implicitSpringDamper>1</implicitSpringDamper>
    <mu1>100000</mu1>
    <mu2>100000</mu2>
    <kp>100000000.0</kp>
    <kd>1.0</kd>
  </gazebo>
  <link name="left_gripper_finger2_knuckle_link">
    <visual>
      <geometry>
        <mesh filename="package://movo_description/meshes/manipulation/robotiq/visual/robotiq_85_knuckle_link.dae"/>
      </geometry>
    </visual>
    <collision>
      <geometry>
        <mesh filename="package://movo_description/meshes/manipulation/robotiq/collision/robotiq_85_knuckle_link.stl"/>
      </geometry>
    </collision>
    <inertial>
      <mass value="0.018491"/>
      <origin xyz="0.0 0.0 0.0"/>
      <inertia ixx="0.000009" ixy="-0.000001" ixz="0.000000" iyx="-0.000001" iyy="0.000001" iyz="0.000000" izx="0.000000" izy="0.000000" izz="0.000010"/>
    </inertial>
  </link>
  <gazebo reference="left_gripper_finger2_knuckle_link">
    <implicitSpringDamper>1</implicitSpringDamper>
    <mu1>100000</mu1>
    <mu2>100000</mu2>
    <kp>100000000.0</kp>
    <kd>1.0</kd>
  </gazebo>
  <joint name="left_gripper_finger1_finger_joint" type="fixed">
    <parent link="left_gripper_finger1_knuckle_link"/>
    <child link="left_gripper_finger1_finger_link"/>
    <origin rpy="0 0 0" xyz="-0.00408552455 -0.03148604435 0.0"/>
  </joint>
  <joint name="left_gripper_finger2_finger_joint" type="fixed">
    <parent link="left_gripper_finger2_knuckle_link"/>
    <child link="left_gripper_finger2_finger_link"/>
    <origin rpy="0 0 0" xyz="-0.00408552455 -0.03148604435 0.0"/>
  </joint>
  <link name="left_gripper_finger1_finger_link">
    <visual>
      <geometry>
        <mesh filename="package://movo_description/meshes/manipulation/robotiq/visual/robotiq_85_finger_link.dae"/>
      </geometry>
    </visual>
    <collision>
      <geometry>
        <mesh filename="package://movo_description/meshes/manipulation/robotiq/collision/robotiq_85_finger_link.stl"/>
      </geometry>
    </collision>
    <inertial>
      <mass value="0.027309"/>
      <origin xyz="0.0 0.0 0.0"/>
      <inertia ixx="0.000003" ixy="-0.000002" ixz="0.000000" iyx="-0.000002" iyy="0.000021" iyz="0.000000" izx="0.000000" izy="0.000000" izz="0.000020"/>
    </inertial>
  </link>
  <gazebo reference="left_gripper_finger1_finger_link">
    <implicitSpringDamper>1</implicitSpringDamper>
    <mu1>100000</mu1>
    <mu2>100000</mu2>
    <kp>100000000.0</kp>
    <kd>1.0</kd>
  </gazebo>
  <link name="left_gripper_finger2_finger_link">
    <visual>
      <geometry>
        <mesh filename="package://movo_description/meshes/manipulation/robotiq/visual/robotiq_85_finger_link.dae"/>
      </geometry>
    </visual>
    <collision>
      <geometry>
        <mesh filename="package://movo_description/meshes/manipulation/robotiq/collision/robotiq_85_finger_link.stl"/>
      </geometry>
    </collision>
    <inertial>
      <mass value="0.027309"/>
      <origin xyz="0.0 0.0 0.0"/>
      <inertia ixx="0.000003" ixy="-0.000002" ixz="0.000000" iyx="-0.000002" iyy="0.000021" iyz="0.000000" izx="0.000000" izy="0.000000" izz="0.000020"/>
    </inertial>
  </link>
  <gazebo reference="left_gripper_finger2_finger_link">
    <implicitSpringDamper>1</implicitSpringDamper>
    <mu1>100000</mu1>
    <mu2>100000</mu2>
    <kp>100000000.0</kp>
    <kd>1.0</kd>
  </gazebo>
  <joint name="left_gripper_finger1_inner_knuckle_joint" type="continuous">
    <parent link="left_gripper_base_link"/>
    <child link="left_gripper_finger1_inner_knuckle_link"/>
    <axis xyz="0 0 1"/>
    <origin rpy="3.14159265 0.0 0.0" xyz="0.06142 0.0127 0"/>
    <limit effort="0.1" lower="-3.14" upper="3.14" velocity="100.0"/>
    <mimic joint="left_gripper_finger1_joint" offset="0"/>
  </joint>
  <joint name="left_gripper_finger2_inner_knuckle_joint" type="continuous">
    <parent link="left_gripper_base_link"/>
    <child link="left_gripper_finger2_inner_knuckle_link"/>
    <axis xyz="0 0 1"/>
    <origin rpy="0 0 0" xyz="0.06142 -0.0127 0"/>
    <limit effort="0.1" lower="-3.14" upper="3.14" velocity="100.0"/>
    <mimic joint="left_gripper_finger1_joint" offset="0"/>
  </joint>
  <link name="left_gripper_finger1_inner_knuckle_link">
    <visual>
      <geometry>
        <mesh filename="package://movo_description/meshes/manipulation/robotiq/visual/robotiq_85_inner_knuckle_link.dae"/>
      </geometry>
    </visual>
    <collision>
      <geometry>
        <mesh filename="package://movo_description/meshes/manipulation/robotiq/collision/robotiq_85_inner_knuckle_link.stl"/>
      </geometry>
    </collision>
    <inertial>
      <mass value="0.029951"/>
      <origin xyz="0.0 0.0 0.0"/>
      <inertia ixx="0.000039" ixy="0.000000" ixz="0.000000" iyx="0.000000" iyy="0.000005" iyz="0.000000" izx="0.000000" izy="0.000000" izz="0.000035"/>
    </inertial>
  </link>
  <gazebo reference="left_gripper_finger1_inner_knuckle_link">
    <implicitSpringDamper>1</implicitSpringDamper>
    <mu1>100000</mu1>
    <mu2>100000</mu2>
    <kp>100000000.0</kp>
    <kd>1.0</kd>
  </gazebo>
  <link name="left_gripper_finger2_inner_knuckle_link">
    <visual>
      <geometry>
        <mesh filename="package://movo_description/meshes/manipulation/robotiq/visual/robotiq_85_inner_knuckle_link.dae"/>
      </geometry>
    </visual>
    <collision>
      <geometry>
        <mesh filename="package://movo_description/meshes/manipulation/robotiq/collision/robotiq_85_inner_knuckle_link.stl"/>
      </geometry>
    </collision>
    <inertial>
      <mass value="0.029951"/>
      <origin xyz="0.0 0.0 0.0"/>
      <inertia ixx="0.000039" ixy="0.000000" ixz="0.000000" iyx="0.000000" iyy="0.000005" iyz="0.000000" izx="0.000000" izy="0.000000" izz="0.000035"/>
    </inertial>
  </link>
  <gazebo reference="left_gripper_finger2_inner_knuckle_link">
    <implicitSpringDamper>1</implicitSpringDamper>
    <mu1>100000</mu1>
    <mu2>100000</mu2>
    <kp>100000000.0</kp>
    <kd>1.0</kd>
  </gazebo>
  <joint name="left_gripper_finger1_finger_tip_joint" type="continuous">
    <parent link="left_gripper_finger1_inner_knuckle_link"/>
    <child link="left_gripper_finger1_finger_tip_link"/>
    <axis xyz="0 0 1"/>
    <origin rpy="0.0 0.0 0.0" xyz="0.04303959807 -0.03759940821 0.0"/>
    <limit effort="0.1" lower="-3.14" upper="3.14" velocity="100.0"/>
    <mimic joint="left_gripper_finger1_joint" multiplier="-1"/>
  </joint>
  <joint name="left_gripper_finger2_finger_tip_joint" type="continuous">
    <parent link="left_gripper_finger2_inner_knuckle_link"/>
    <child link="left_gripper_finger2_finger_tip_link"/>
    <axis xyz="0 0 1"/>
    <origin rpy="0.0 0.0 0.0" xyz="0.04303959807 -0.03759940821  0.0"/>
    <limit effort="0.1" lower="-3.14" upper="3.14" velocity="100.0"/>
    <mimic joint="left_gripper_finger1_joint" multiplier="-1"/>
  </joint>
  <link name="left_gripper_finger1_finger_tip_link">
    <visual>
      <geometry>
        <mesh filename="package://movo_description/meshes/manipulation/robotiq/visual/robotiq_85_finger_tip_link.dae"/>
      </geometry>
    </visual>
    <collision>
      <geometry>
        <mesh filename="package://movo_description/meshes/manipulation/robotiq/collision/robotiq_85_finger_tip_link.stl"/>
      </geometry>
    </collision>
    <inertial>
      <mass value="0.019555"/>
      <origin xyz="0.0 0.0 0.0"/>
      <inertia ixx="0.000002" ixy="0.000000" ixz="0.000000" iyx="0.000000" iyy="0.000005" iyz="0.000000" izx="0.000000" izy="0.000000" izz="0.000006"/>
    </inertial>
  </link>
  <gazebo reference="left_gripper_finger1_finger_tip_link">
    <implicitSpringDamper>1</implicitSpringDamper>
    <mu1>100000</mu1>
    <mu2>100000</mu2>
    <kp>100000000.0</kp>
    <kd>1.0</kd>
  </gazebo>
  <link name="left_gripper_finger2_finger_tip_link">
    <visual>
      <geometry>
        <mesh filename="package://movo_description/meshes/manipulation/robotiq/visual/robotiq_85_finger_tip_link.dae"/>
      </geometry>
    </visual>
    <collision>
      <geometry>
        <mesh filename="package://movo_description/meshes/manipulation/robotiq/collision/robotiq_85_finger_tip_link.stl"/>
      </geometry>
    </collision>
    <inertial>
      <mass value="0.019555"/>
      <origin xyz="0.0 0.0 0.0"/>
      <inertia ixx="0.000002" ixy="0.000000" ixz="0.000000" iyx="0.000000" iyy="0.000005" iyz="0.000000" izx="0.000000" izy="0.000000" izz="0.000006"/>
    </inertial>
  </link>
  <gazebo reference="left_gripper_finger2_finger_tip_link">
    <implicitSpringDamper>1</implicitSpringDamper>
    <mu1>100000</mu1>
    <mu2>100000</mu2>
    <kp>100000000.0</kp>
    <kd>1.0</kd>
  </gazebo>
  <transmission name="left_gripper_finger1_trans">
    <type>transmission_interface/SimpleTransmission</type>
    <joint name="left_gripper_finger1_joint">
      <hardwareInterface>PositionJointInterface</hardwareInterface>
    </joint>
    <actuator name="left_gripper_finger1_motor">
      <mechanicalReduction>1</mechanicalReduction>
      <hardwareInterface>PositionJointInterface</hardwareInterface>
    </actuator>
  </transmission>
  <gazebo>
    <!-- loading plugin: mimic joints works in gazebo now -->
    <plugin filename="libroboticsgroup_gazebo_mimic_joint_plugin.so" name="left_mimic_robotiq_85_1">
      <joint>left_gripper_finger1_joint</joint>
      <mimicJoint>left_gripper_finger2_joint</mimicJoint>
      <!--multiplier>1.0</multiplier>
                <offset>0.0</offset-->
    </plugin>
    <plugin filename="libroboticsgroup_gazebo_mimic_joint_plugin.so" name="left_mimic_robotiq_85_2">
      <joint>left_gripper_finger1_joint</joint>
      <mimicJoint>left_gripper_finger2_inner_knuckle_joint</mimicJoint>
      <!--multiplier>1.0</multiplier>
                <offset>0.0</offset-->
    </plugin>
    <plugin filename="libroboticsgroup_gazebo_mimic_joint_plugin.so" name="left_mimic_robotiq_85_3">
      <joint>left_gripper_finger1_joint</joint>
      <mimicJoint>left_gripper_finger1_inner_knuckle_joint</mimicJoint>
      <!--multiplier>1.0</multiplier>
                <offset>0.0</offset-->
    </plugin>
    <plugin filename="libroboticsgroup_gazebo_mimic_joint_plugin.so" name="left_mimic_robotiq_85_4">
      <joint>left_gripper_finger1_joint</joint>
      <mimicJoint>left_gripper_finger1_finger_tip_joint</mimicJoint>
      <multiplier>-1.0</multiplier>
      <offset>0.0</offset>
    </plugin>
    <plugin filename="libroboticsgroup_gazebo_mimic_joint_plugin.so" name="left_mimic_robotiq_85_5">
      <joint>left_gripper_finger1_joint</joint>
      <mimicJoint>left_gripper_finger2_finger_tip_joint</mimicJoint>
      <multiplier>-1.0</multiplier>
      <offset>0.0</offset>
    </plugin>
  </gazebo>
  <gazebo>
    <plugin filename="libgazebo_grasp_fix.so" name="gazebo_left_grasp_fix">
      <arm>
        <arm_name>left_arm</arm_name>
        <palm_link> left_wrist_3_link </palm_link>
        <gripper_link> left_gripper_finger1_knuckle_link </gripper_link>
        <gripper_link> left_gripper_finger1_finger_link </gripper_link>
        <gripper_link> left_gripper_finger1_inner_knuckle_link </gripper_link>
        <gripper_link> left_gripper_finger1_finger_tip_link </gripper_link>
        <gripper_link> left_gripper_finger2_knuckle_link </gripper_link>
        <gripper_link> left_gripper_finger2_finger_link </gripper_link>
        <gripper_link> left_gripper_finger2_inner_knuckle_link </gripper_link>
        <gripper_link> left_gripper_finger2_finger_tip_link </gripper_link>
      </arm>
      <forces_angle_tolerance>90</forces_angle_tolerance>
      <update_rate>100</update_rate>
      <grip_count_threshold>1</grip_count_threshold>
      <max_grip_count>2</max_grip_count>
      <release_tolerance>0.005</release_tolerance>
      <disable_collisions_on_attach>true</disable_collisions_on_attach>
      <contact_topic>left_gripper/contacts</contact_topic>
    </plugin>
  </gazebo>
</robot>

