<?xml version="1.0" ?>
<sdf version='1.6'>
  <model name='movo_robotiq'>    
    <link name='base_link'>
      <pose frame=''>0 0 0 0 -0 0</pose>
      <inertial>
        <pose frame=''>-0.003376 -0.009598 0.234445 0 -0 0</pose>
        <mass>60.165</mass>
        <inertia>
          <ixx>3.62586</ixx>
          <ixy>-0.0034936</ixy>
          <ixz>-0.0758314</ixz>
          <iyy>3.63679</iyy>
          <iyz>-0.0727875</iyz>
          <izz>0.107862</izz>
        </inertia>
      </inertial>          
      <!--collision name='base_link_fixed_joint_lump__base_chassis_link_collision'>
        <pose frame=''>0 0 0.0762 0 -0 0</pose>
        <geometry>
          <mesh>
            <scale>1 1 1</scale>
            <uri>file://movo_robotiq/meshes/movo_components/collision/vector_base_collision.stl</uri>
          </mesh>
        </geometry>        
      </collision>
      <collision name='base_link_fixed_joint_lump__front_laser_link_collision_1'>
        <pose frame=''>0.3375 0 0.220111 3.14159 -0 0</pose>
        <geometry>
          <box>
            <size>0.1 0.1 0.1</size>
          </box>
        </geometry>        
      </collision>
      <collision name='base_link_fixed_joint_lump__linear_actuator_fixed_link_collision_2'>
        <pose frame=''>0 0 0.0762 0 -0 0</pose>
        <geometry>
          <mesh>
            <scale>1 1 1</scale>
            <uri>file://movo_robotiq/meshes/movo_components/collision/movo_fixed_body_collision.stl</uri>
          </mesh>
        </geometry>        
      </collision>
      <collision name='base_link_fixed_joint_lump__rear_laser_link_collision_3'>
        <pose frame=''>-0.3375 0 0.220111 3.14159 -0 3.14159</pose>
        <geometry>
          <box>
            <size>0.1 0.1 0.1</size>
          </box>
        </geometry>        
      </collision-->
      <visual name='base_link_fixed_joint_lump__base_chassis_link_visual'>
        <pose frame=''>0 0 0.0762 0 -0 0</pose>
        <geometry>
          <mesh>
            <scale>1 1 1</scale>
            <uri>file://movo_robotiq/meshes/movo_components/visual/vector_base.dae</uri>
          </mesh>
        </geometry>
        <material>
          <script>
            <uri>__default__</uri>
            <name>__default__</name>
          </script>
        </material>
      </visual>
      <visual name='base_link_fixed_joint_lump__front_laser_link_visual_1'>
        <pose frame=''>0.3375 0 0.220111 3.14159 -0 0</pose>
        <geometry>
          <mesh>
            <scale>1 1 1</scale>
            <uri>file://movo_robotiq/meshes/sensors/visual/sick_tim.dae</uri>
          </mesh>
        </geometry>
        <material>
          <script>
            <uri>__default__</uri>
            <name>__default__</name>
          </script>
        </material>
      </visual>
      <visual name='base_link_fixed_joint_lump__linear_actuator_fixed_link_visual_2'>
        <pose frame=''>0 0 0.0762 0 -0 0</pose>
        <geometry>
          <mesh>
            <scale>1 1 1</scale>
            <uri>file://movo_robotiq/meshes/movo_components/visual/movo_fixed_payload.dae</uri>
          </mesh>
        </geometry>
        <material>
          <script>
            <uri>__default__</uri>
            <name>__default__</name>
          </script>
        </material>
      </visual>
      <visual name='base_link_fixed_joint_lump__rear_laser_link_visual_3'>
        <pose frame=''>-0.3375 0 0.220111 3.14159 -0 3.14159</pose>
        <geometry>
          <mesh>
            <scale>1 1 1</scale>
            <uri>file://movo_robotiq/meshes/sensors/visual/sick_tim.dae</uri>
          </mesh>
        </geometry>
        <material>
          <script>
            <uri>__default__</uri>
            <name>__default__</name>
          </script>
        </material>
      </visual>      
      <gravity>1</gravity>
      <velocity_decay/>      
    </link>
    <link name='linear_actuator_link'>
      <pose frame=''>0.07714 0 0.470076 0 -0 0</pose>
      <inertial>
        <pose frame=''>-0.06514 -0.002828 0.356497 0 -0 0</pose>
        <mass>20.7437</mass>
        <inertia>
          <ixx>0.8115</ixx>
          <ixy>-0.0106441</ixy>
          <ixz>-0.0608701</ixz>
          <iyy>0.839619</iyy>
          <iyz>-0.022887</iyz>
          <izz>0.666234</izz>
        </inertia>
      </inertial>
      <!--collision name='linear_actuator_link_collision'>
        <pose frame=''>0 0 0 0 -0 0</pose>
        <geometry>
          <mesh>
            <scale>1 1 1</scale>
            <uri>file://movo_robotiq/meshes/movo_components/collision/movo_upper_body_collision.stl</uri>
          </mesh>
        </geometry>
        <surface>
          <contact>
            <ode/>
          </contact>
          <friction>
            <ode/>
          </friction>
        </surface>
        <laser_retro>0</laser_retro>
      </collision>
      <collision name='linear_actuator_link_fixed_joint_lump__left_base_link_collision_1'>
        <pose frame=''>0.026105 0.13335 0.279994 -1.5708 -0 -1.5708</pose>
        <geometry>
          <mesh>
            <scale>1 1 1</scale>
            <uri>file://movo_robotiq/meshes/manipulation/jaco/collision/base.stl</uri>
          </mesh>
        </geometry>
        <surface>
          <contact>
            <ode>
              <kp>1e+06</kp>
              <kd>100</kd>
              <max_vel>100</max_vel>
              <min_depth>0.001</min_depth>
            </ode>
          </contact>
          <friction>
            <ode>
              <mu>1</mu>
              <mu2>1</mu2>
            </ode>
          </friction>
        </surface>
      </collision>
      <collision name='linear_actuator_link_fixed_joint_lump__pan_base_link_collision_2'>
        <pose frame=''>0.19735 0 0.344989 0 -0 0</pose>
        <geometry>
          <mesh>
            <scale>1 1 1</scale>
            <uri>file://movo_robotiq/meshes/pan_tilt/collision/pan_tilt_base.stl</uri>
          </mesh>
        </geometry>
      </collision-->
      <visual name='linear_actuator_link_visual'>
        <pose frame=''>0 0 0 0 -0 0</pose>
        <geometry>
          <mesh>
            <scale>1 1 1</scale>
            <uri>file://movo_robotiq/meshes/movo_components/visual/movo_moving_payload.dae</uri>
          </mesh>
        </geometry>
        <material>
          <script>
            <uri>__default__</uri>
            <name>__default__</name>
          </script>
        </material>
      </visual>
      <visual name='linear_actuator_link_fixed_joint_lump__left_base_link_visual_1'>
        <pose frame=''>0.026105 0.13335 0.279994 -1.5708 -0 -1.5708</pose>
        <geometry>
          <mesh>
            <scale>1 1 1</scale>
            <uri>file://movo_robotiq/meshes/manipulation/jaco/visual/base.dae</uri>
          </mesh>
        </geometry>
        <material>
          <script>
            <uri>__default__</uri>
            <name>__default__</name>
          </script>
        </material>
      </visual>
      <visual name='linear_actuator_link_fixed_joint_lump__pan_base_link_visual_2'>
        <pose frame=''>0.19735 0 0.344989 0 -0 0</pose>
        <geometry>
          <mesh>
            <scale>1 1 1</scale>
            <uri>file://movo_robotiq/meshes/pan_tilt/visual/pan_tilt_base.dae</uri>
          </mesh>
        </geometry>
      </visual>
      <velocity_decay/>
      <gravity>1</gravity>
      <velocity_decay/>
    </link>
    <joint name='linear_joint' type='prismatic'>
      <child>linear_actuator_link</child>
      <parent>base_link</parent>
      <axis>
        <xyz>0 0 1</xyz>
        <limit>
          <lower>0</lower>
          <upper>0.472</upper>
          <effort>1000</effort>
          <velocity>0.2</velocity>
        </limit>
        <dynamics>
          <damping>0</damping>
          <friction>0</friction>
          <spring_reference>0</spring_reference>
          <spring_stiffness>0</spring_stiffness>
        </dynamics>
        <use_parent_model_frame>1</use_parent_model_frame>
      </axis>
    </joint>
    <link name='left_shoulder_link'>
      <pose frame=''>0.165745 0.13335 0.75007 -1.5708 0 1.5708</pose>
      <inertial>
        <pose frame=''>1.8e-05 -0.004667 -0.060609 0 -0 0</pose>
        <mass>0.824524</mass>
        <inertia>
          <ixx>0.002561</ixx>
          <ixy>0</ixy>
          <ixz>1e-06</ixz>
          <iyy>0.002653</iyy>
          <iyz>0.000212</iyz>
          <izz>0.000524</izz>
        </inertia>
      </inertial>
      <collision name='left_shoulder_link_collision'>
        <pose frame=''>0 0 0 0 -0 0</pose>
        <geometry>
          <mesh>
            <scale>1 1 1</scale>
            <uri>file://movo_robotiq/meshes/manipulation/jaco/collision/shoulder_7dof.stl</uri>
          </mesh>
        </geometry>
        <surface>
          <contact>
            <ode>
              <kp>1e+06</kp>
              <kd>100</kd>
              <max_vel>100</max_vel>
              <min_depth>0.001</min_depth>
            </ode>
          </contact>
          <friction>
            <ode>
              <mu>1</mu>
              <mu2>1</mu2>
            </ode>
          </friction>
        </surface>
      </collision>
      <visual name='left_shoulder_link_visual'>
        <pose frame=''>0 0 0 0 -0 0</pose>
        <geometry>
          <mesh>
            <scale>1 1 1</scale>
            <uri>file://movo_robotiq/meshes/manipulation/jaco/visual/shoulder_7dof.dae</uri>
          </mesh>
        </geometry>
        <material>
          <script>
            <uri>__default__</uri>
            <name>__default__</name>
          </script>
        </material>
      </visual>
      <gravity>1</gravity>
      <velocity_decay/>
    </link>
    <joint name='left_shoulder_pan_joint' type='revolute'>
      <child>left_shoulder_link</child>
      <parent>linear_actuator_link</parent>
      <axis>
        <xyz>-1 -0 -0</xyz>
        <limit>
          <lower>-300000.14159</lower>
          <upper>300000.14159</upper>
          <effort>18000</effort>
          <velocity>0.69115</velocity>
        </limit>
        <dynamics>
          <damping>0.01</damping>
          <friction>0</friction>
          <spring_reference>0</spring_reference>
          <spring_stiffness>0</spring_stiffness>
        </dynamics>
        <use_parent_model_frame>1</use_parent_model_frame>
      </axis>
    </joint>
    <link name='left_arm_half_1_link'>
      <pose frame=''>0.284495 0.13335 0.75007 -0 0 1.5708</pose>
      <inertial>
        <pose frame=''>0 -0.103563 0 0 -0 0</pose>
        <mass>0.8447</mass>
        <inertia>
          <ixx>0.000435</ixx>
          <ixy>2e-06</ixy>
          <ixz>0.000231</ixz>
          <iyy>0.034947</iyy>
          <iyz>0</iyz>
          <izz>0.035198</izz>
        </inertia>
      </inertial>
      <collision name='left_arm_half_1_link_collision'>
        <pose frame=''>0 0 0 0 -0 0</pose>
        <geometry>
          <mesh>
            <scale>1 1 1</scale>
            <uri>file://movo_robotiq/meshes/manipulation/jaco/collision/arm_half_1.stl</uri>
          </mesh>
        </geometry>
        <surface>
          <contact>
            <ode>
              <kp>1e+06</kp>
              <kd>100</kd>
              <max_vel>100</max_vel>
              <min_depth>0.001</min_depth>
            </ode>
          </contact>
          <friction>
            <ode>
              <mu>1</mu>
              <mu2>1</mu2>
            </ode>
          </friction>
        </surface>
      </collision>
      <visual name='left_arm_half_1_link_visual'>
        <pose frame=''>0 0 0 0 -0 0</pose>
        <geometry>
          <mesh>
            <scale>1 1 1</scale>
            <uri>file://movo_robotiq/meshes/manipulation/jaco/visual/arm_half_1.dae</uri>
          </mesh>
        </geometry>
        <material>
          <script>
            <uri>__default__</uri>
            <name>__default__</name>
          </script>
        </material>
      </visual>
      <gravity>1</gravity>
      <velocity_decay/>
    </link>
    <joint name='left_shoulder_lift_joint' type='revolute'>
      <child>left_arm_half_1_link</child>
      <parent>left_shoulder_link</parent>
      <axis>
        <xyz>-0 0 1</xyz>
        <limit>
          <lower>-200000.238</lower>
          <upper>200000.238</upper>
          <effort>30000.5</effort>
          <velocity>0.69115</velocity>
        </limit>
        <dynamics>
          <damping>0.01</damping>
          <friction>0</friction>
          <spring_reference>0</spring_reference>
          <spring_stiffness>0</spring_stiffness>
        </dynamics>
        <use_parent_model_frame>1</use_parent_model_frame>
      </axis>
    </joint>
    <link name='left_arm_half_2_link'>
      <pose frame=''>0.489495 0.13335 0.75007 -1.5708 0 1.5708</pose>
      <inertial>
        <pose frame=''>0 0 -0.102245 0 -0 0</pose>
        <mass>0.8447</mass>
        <inertia>
          <ixx>0.000435</ixx>
          <ixy>2e-06</ixy>
          <ixz>0.000231</ixz>
          <iyy>0.034947</iyy>
          <iyz>0</iyz>
          <izz>0.035198</izz>
        </inertia>
      </inertial>
      <collision name='left_arm_half_2_link_collision'>
        <pose frame=''>0 0 0 0 -0 0</pose>
        <geometry>
          <mesh>
            <scale>1 1 1</scale>
            <uri>file://movo_robotiq/meshes/manipulation/jaco/collision/arm_half_2.stl</uri>
          </mesh>
        </geometry>
        <surface>
          <contact>
            <ode>
              <kp>1e+06</kp>
              <kd>100</kd>
              <max_vel>100</max_vel>
              <min_depth>0.001</min_depth>
            </ode>
          </contact>
          <friction>
            <ode>
              <mu>1</mu>
              <mu2>1</mu2>
            </ode>
          </friction>
        </surface>
      </collision>
      <visual name='left_arm_half_2_link_visual'>
        <pose frame=''>0 0 0 0 -0 0</pose>
        <geometry>
          <mesh>
            <scale>1 1 1</scale>
            <uri>file://movo_robotiq/meshes/manipulation/jaco/visual/arm_half_2.dae</uri>
          </mesh>
        </geometry>
        <material>
          <script>
            <uri>__default__</uri>
            <name>__default__</name>
          </script>
        </material>
      </visual>
      <gravity>1</gravity>
      <velocity_decay/>
    </link>
    <joint name='left_arm_half_joint' type='revolute'>
      <child>left_arm_half_2_link</child>
      <parent>left_arm_half_1_link</parent>
      <axis>
        <xyz>-1 -0 -0</xyz>
        <limit>
          <lower>-300000.14159</lower>
          <upper>300000.14159</upper>
          <effort>30000.5</effort>
          <velocity>0.69115</velocity>
        </limit>
        <dynamics>
          <damping>0.01</damping>
          <friction>0</friction>
          <spring_reference>0</spring_reference>
          <spring_stiffness>0</spring_stiffness>
        </dynamics>
        <use_parent_model_frame>1</use_parent_model_frame>
      </axis>
    </joint>
    <link name='left_forearm_link'>
      <pose frame=''>0.694495 0.13335 0.75007 -3.14159 0 1.5708</pose>
      <inertial>
        <pose frame=''>0 0.081 -0.0086 0 -0 0</pose>
        <mass>0.674254</mass>
        <inertia>
          <ixx>0.005453</ixx>
          <ixy>3e-06</ixy>
          <ixz>0</ixz>
          <iyy>0.000305</iyy>
          <iyz>8.7e-05</iyz>
          <izz>0.005578</izz>
        </inertia>
      </inertial>
      <collision name='left_forearm_link_collision'>
        <pose frame=''>0 0 0 0 -0 0</pose>
        <geometry>
          <mesh>
            <scale>1 1 1</scale>
            <uri>file://movo_robotiq/meshes/manipulation/jaco/collision/forearm_7dof.stl</uri>
          </mesh>
        </geometry>
      </collision>
      <visual name='left_forearm_link_visual'>
        <pose frame=''>0 0 0 0 -0 0</pose>
        <geometry>
          <mesh>
            <scale>1 1 1</scale>
            <uri>file://movo_robotiq/meshes/manipulation/jaco/visual/forearm_7dof.dae</uri>
          </mesh>
        </geometry>
      </visual>
    </link>
    <joint name='left_elbow_joint' type='revolute'>
      <child>left_forearm_link</child>
      <parent>left_arm_half_2_link</parent>
      <axis>
        <xyz>-0 -0 -1</xyz>
        <limit>
          <lower>-200000.809</lower>
          <upper>200000.809</upper>
          <effort>18000</effort>
          <velocity>0.69115</velocity>
        </limit>
        <dynamics>
          <damping>0.01</damping>
          <friction>0</friction>
          <spring_reference>0</spring_reference>
          <spring_stiffness>0</spring_stiffness>
        </dynamics>
        <use_parent_model_frame>1</use_parent_model_frame>
      </axis>
    </joint>
    <link name='left_wrist_spherical_1_link'>
      <pose frame=''>0.901795 0.13335 0.76147 1.5708 -0 -1.5708</pose>
      <inertial>
        <pose frame=''>0 0.002885 -0.054193 0 -0 0</pose>
        <mass>0.463</mass>
        <inertia>
          <ixx>0.000392</ixx>
          <ixy>0</ixy>
          <ixz>0</ixz>
          <iyy>0.000347</iyy>
          <iyz>0.000101</iyz>
          <izz>0.000233</izz>
        </inertia>
      </inertial>
      <collision name='left_wrist_spherical_1_link_collision'>
        <pose frame=''>0 0 0 0 -0 0</pose>
        <geometry>
          <mesh>
            <scale>1 1 1</scale>
            <uri>file://movo_robotiq/meshes/manipulation/jaco/collision/wrist_spherical_1.stl</uri>
          </mesh>
        </geometry>
        <surface>
          <contact>
            <ode>
              <kp>1e+06</kp>
              <kd>100</kd>
              <max_vel>100</max_vel>
              <min_depth>0.001</min_depth>
            </ode>
          </contact>
          <friction>
            <ode>
              <mu>1</mu>
              <mu2>1</mu2>
            </ode>
          </friction>
        </surface>
      </collision>
      <visual name='left_wrist_spherical_1_link_visual'>
        <pose frame=''>0 0 0 0 -0 0</pose>
        <geometry>
          <mesh>
            <scale>1 1 1</scale>
            <uri>file://movo_robotiq/meshes/manipulation/jaco/visual/wrist_spherical_1.dae</uri>
          </mesh>
        </geometry>
        <material>
          <script>
            <uri>__default__</uri>
            <name>__default__</name>
          </script>
        </material>
      </visual>
      <gravity>1</gravity>
      <velocity_decay/>
    </link>
    <joint name='left_wrist_spherical_1_joint' type='revolute'>
      <child>left_wrist_spherical_1_link</child>
      <parent>left_forearm_link</parent>
      <axis>
        <xyz>-1 -0 0</xyz>
        <limit>
          <lower>-300000.14159</lower>
          <upper>300000.14159</upper>
          <effort>60000.8</effort>
          <velocity>0.921534</velocity>
        </limit>
        <dynamics>
          <damping>0.01</damping>
          <friction>0</friction>
          <spring_reference>0</spring_reference>
          <spring_stiffness>0</spring_stiffness>
        </dynamics>
        <use_parent_model_frame>1</use_parent_model_frame>
      </axis>
    </joint>
    <link name='left_wrist_spherical_2_link'>
      <pose frame=''>1.00554 0.13335 0.76147 -0 -0 -1.5708</pose>
      <inertial>
        <pose frame=''>0 0.049721 -0.002856 0 -0 0</pose>
        <mass>0.463</mass>
        <inertia>
          <ixx>0.000392</ixx>
          <ixy>0</ixy>
          <ixz>0</ixz>
          <iyy>0.000347</iyy>
          <iyz>0.000101</iyz>
          <izz>0.000233</izz>
        </inertia>
      </inertial>
      <collision name='left_wrist_spherical_2_link_collision'>
        <pose frame=''>0 0 0 0 -0 0</pose>
        <geometry>
          <mesh>
            <scale>1 1 1</scale>
            <uri>file://movo_robotiq/meshes/manipulation/jaco/collision/wrist_spherical_2.stl</uri>
          </mesh>
        </geometry>
        <surface>
          <contact>
            <ode>
              <kp>1e+06</kp>
              <kd>100</kd>
              <max_vel>100</max_vel>
              <min_depth>0.001</min_depth>
            </ode>
          </contact>
          <friction>
            <ode>
              <mu>1</mu>
              <mu2>1</mu2>
            </ode>
          </friction>
        </surface>
      </collision>
      <visual name='left_wrist_spherical_2_link_visual'>
        <pose frame=''>0 0 0 0 -0 0</pose>
        <geometry>
          <mesh>
            <scale>1 1 1</scale>
            <uri>file://movo_robotiq/meshes/manipulation/jaco/visual/wrist_spherical_2.dae</uri>
          </mesh>
        </geometry>
        <material>
          <script>
            <uri>__default__</uri>
            <name>__default__</name>
          </script>
        </material>
      </visual>
      <gravity>1</gravity>
      <velocity_decay/>
    </link>
    <joint name='left_wrist_spherical_2_joint' type='revolute'>
      <child>left_wrist_spherical_2_link</child>
      <parent>left_wrist_spherical_1_link</parent>
      <axis>
        <xyz>0 0 1</xyz>
        <limit>
          <lower>-200000.78</lower>
          <upper>200000.78</upper>
          <effort>60000.8</effort>
          <velocity>0.921534</velocity>
        </limit>
        <dynamics>
          <damping>0.01</damping>
          <friction>0</friction>
          <spring_reference>0</spring_reference>
          <spring_stiffness>0</spring_stiffness>
        </dynamics>
        <use_parent_model_frame>1</use_parent_model_frame>
      </axis>
    </joint>
    <link name='left_wrist_3_link'>
      <pose frame=''>1.10929 0.13335 0.76147 -1.5708 0 1.5708</pose>
      <inertial>
        <pose frame=''>-0.000169 1e-05 -0.079493 0 -0 0</pose>
        <mass>0.927733</mass>
        <inertia>
          <ixx>0.00586758</ixx>
          <ixy>5.96473e-09</ixy>
          <ixz>-2.13742e-05</ixz>
          <iyy>0.00592968</iyy>
          <iyz>1.25117e-06</iyz>
          <izz>0.000453102</izz>
        </inertia>
      </inertial>
      <collision name='left_wrist_3_link_collision'>
        <pose frame=''>0 0 0 0 -0 0</pose>
        <geometry>
          <mesh>
            <scale>1 1 1</scale>
            <uri>file://movo_robotiq/meshes/manipulation/jaco/collision/kinova_actuator_gearing.stl</uri>
          </mesh>
        </geometry>
        <surface>
          <contact>
            <ode>
              <kp>1e+06</kp>
              <kd>100</kd>
              <max_vel>100</max_vel>
              <min_depth>0.001</min_depth>
            </ode>
          </contact>
          <friction>
            <ode>
              <mu>1</mu>
              <mu2>1</mu2>
            </ode>
          </friction>
        </surface>
      </collision>
      <collision name='left_wrist_3_link_fixed_joint_lump__left_robotiq_coupler_link_collision_1'>
        <pose frame=''>-0 0 0 0 -0 0</pose>
        <geometry>
          <mesh>
            <scale>1 1 1</scale>
            <uri>file://movo_robotiq/meshes/manipulation/robotiq/collision/kinova_robotiq_coupler.stl</uri>
          </mesh>
        </geometry>
        <surface>
          <contact>
            <ode>
              <kp>1e+08</kp>
              <kd>1</kd>
            </ode>
          </contact>
          <friction>
            <ode>
              <mu>100000</mu>
              <mu2>100000</mu2>
            </ode>
          </friction>
        </surface>
      </collision>
      <collision name='left_wrist_3_link_fixed_joint_lump__left_gripper_base_link_collision_2'>
        <pose frame=''>-0 0 -0.05105 3.14159 1.57079 -1.57079</pose>
        <geometry>
          <mesh>
            <scale>1 1 1</scale>
            <uri>file://movo_robotiq/meshes/manipulation/robotiq/collision/robotiq_85_base_link.stl</uri>
          </mesh>
        </geometry>
        <surface>
          <contact>
            <ode>
              <kp>1e+08</kp>
              <kd>1</kd>
            </ode>
          </contact>
          <friction>
            <ode>
              <mu>100000</mu>
              <mu2>100000</mu2>
            </ode>
          </friction>
        </surface>
      </collision>
      <visual name='left_wrist_3_link_visual'>
        <pose frame=''>0 0 0 0 -0 0</pose>
        <geometry>
          <mesh>
            <scale>1 1 1</scale>
            <uri>file://movo_robotiq/meshes/manipulation/jaco/visual/kinova_actuator_gearing.dae</uri>
          </mesh>
        </geometry>
        <material>
          <script>
            <uri>__default__</uri>
            <name>__default__</name>
          </script>
        </material>
      </visual>
      <visual name='left_wrist_3_link_fixed_joint_lump__left_robotiq_coupler_link_visual_1'>
        <pose frame=''>-0 0 0 0 -0 0</pose>
        <geometry>
          <mesh>
            <scale>1 1 1</scale>
            <uri>file://movo_robotiq/meshes/manipulation/robotiq/visual/kinova_robotiq_coupler.dae</uri>
          </mesh>
        </geometry>
        <material>
          <script>
            <uri>__default__</uri>
            <name>__default__</name>
          </script>
        </material>
      </visual>
      <visual name='left_wrist_3_link_fixed_joint_lump__left_gripper_base_link_visual_2'>
        <pose frame=''>-0 0 -0.05105 3.14159 1.57079 -1.57079</pose>
        <geometry>
          <mesh>
            <scale>1 1 1</scale>
            <uri>file://movo_robotiq/meshes/manipulation/robotiq/visual/robotiq_85_base_link.dae</uri>
          </mesh>
        </geometry>
        <material>
          <script>
            <uri>__default__</uri>
            <name>__default__</name>
          </script>
        </material>
      </visual>
      <velocity_decay/>
      <velocity_decay/>
      <gravity>1</gravity>
      <velocity_decay/>
    </link>
    <joint name='left_wrist_3_joint' type='revolute'>
      <child>left_wrist_3_link</child>
      <parent>left_wrist_spherical_2_link</parent>
      <axis>
        <xyz>-1 -0 -0</xyz>
        <limit>
          <lower>-300000.14159</lower>
          <upper>300000.14159</upper>
          <effort>60000.8</effort>
          <velocity>0.921534</velocity>
        </limit>
        <dynamics>
          <damping>0.01</damping>
          <friction>0</friction>
          <spring_reference>0</spring_reference>
          <spring_stiffness>0</spring_stiffness>
        </dynamics>
        <use_parent_model_frame>1</use_parent_model_frame>
      </axis>
    </joint>
    <link name='left_gripper_finger1_inner_knuckle_link'>
      <pose frame=''>1.22176 0.12065 0.76147 -0 0 0</pose>
      <inertial>
        <pose frame=''>0 0 0 0 -0 0</pose>
        <mass>0.029951</mass>
        <inertia>
          <ixx>3.9e-05</ixx>
          <ixy>0</ixy>
          <ixz>0</ixz>
          <iyy>5e-06</iyy>
          <iyz>0</iyz>
          <izz>3.5e-05</izz>
        </inertia>
      </inertial>
      <collision name='left_gripper_finger1_inner_knuckle_link_collision'>
        <pose frame=''>0 0 0 0 -0 0</pose>
        <geometry>
          <mesh>
            <scale>1 1 1</scale>
            <uri>file://movo_robotiq/meshes/manipulation/robotiq/collision/robotiq_85_inner_knuckle_link.stl</uri>
          </mesh>
        </geometry>
        <surface>
          <contact>
            <ode>
              <kp>1e+08</kp>
              <kd>1</kd>
            </ode>
          </contact>
          <friction>
            <ode>
              <mu>100000</mu>
              <mu2>100000</mu2>
            </ode>
          </friction>
        </surface>
      </collision>
      <visual name='left_gripper_finger1_inner_knuckle_link_visual'>
        <pose frame=''>0 0 0 0 -0 0</pose>
        <geometry>
          <mesh>
            <scale>1 1 1</scale>
            <uri>file://movo_robotiq/meshes/manipulation/robotiq/visual/robotiq_85_inner_knuckle_link.dae</uri>
          </mesh>
        </geometry>
        <material>
          <script>
            <uri>__default__</uri>
            <name>__default__</name>
          </script>
        </material>
      </visual>
      <gravity>1</gravity>
      <velocity_decay/>
    </link>
    <joint name='left_gripper_finger1_inner_knuckle_joint' type='revolute'>
      <child>left_gripper_finger1_inner_knuckle_link</child>
      <parent>left_wrist_3_link</parent>
      <axis>
        <xyz>0 0 1</xyz>
        <limit>
          <lower>-1e+16</lower>
          <upper>1e+16</upper>
        </limit>
        <dynamics>
          <spring_reference>0</spring_reference>
          <spring_stiffness>0</spring_stiffness>
        </dynamics>
        <use_parent_model_frame>1</use_parent_model_frame>
      </axis>
    </joint>
    <link name='left_gripper_finger1_finger_tip_link'>
      <pose frame=''>1.2648 0.083051 0.76147 -0 0 0</pose>
      <inertial>
        <pose frame=''>0 0 0 0 -0 0</pose>
        <mass>0.019555</mass>
        <inertia>
          <ixx>2e-06</ixx>
          <ixy>0</ixy>
          <ixz>0</ixz>
          <iyy>5e-06</iyy>
          <iyz>0</iyz>
          <izz>6e-06</izz>
        </inertia>
      </inertial>
      <collision name='left_gripper_finger1_finger_tip_link_collision'>
        <pose frame=''>0 0 0 0 -0 0</pose>
        <geometry>
          <mesh>
            <scale>1 1 1</scale>
            <uri>file://movo_robotiq/meshes/manipulation/robotiq/collision/robotiq_85_finger_tip_link.stl</uri>
          </mesh>
        </geometry>
        <surface>
          <contact>
            <ode>
              <kp>1e+08</kp>
              <kd>1</kd>
            </ode>
          </contact>
          <friction>
            <ode>
              <mu>100000</mu>
              <mu2>100000</mu2>
            </ode>
          </friction>
        </surface>
      </collision>
      <visual name='left_gripper_finger1_finger_tip_link_visual'>
        <pose frame=''>0 0 0 0 -0 0</pose>
        <geometry>
          <mesh>
            <scale>1 1 1</scale>
            <uri>file://movo_robotiq/meshes/manipulation/robotiq/visual/robotiq_85_finger_tip_link.dae</uri>
          </mesh>
        </geometry>
        <material>
          <script>
            <uri>__default__</uri>
            <name>__default__</name>
          </script>
        </material>
      </visual>
      <gravity>1</gravity>
      <velocity_decay/>
    </link>
    <joint name='left_gripper_finger1_finger_tip_joint' type='revolute'>
      <child>left_gripper_finger1_finger_tip_link</child>
      <parent>left_gripper_finger1_inner_knuckle_link</parent>
      <axis>
        <xyz>0 0 1</xyz>
        <limit>
          <lower>-1e+16</lower>
          <upper>1e+16</upper>
        </limit>
        <dynamics>
          <spring_reference>0</spring_reference>
          <spring_stiffness>0</spring_stiffness>
        </dynamics>
        <use_parent_model_frame>1</use_parent_model_frame>
      </axis>
    </joint>
    <link name='left_gripper_finger1_knuckle_link'>
      <pose frame=''>1.21525 0.102749 0.76147 -0 0 0</pose>
      <inertial>
        <pose frame=''>-0.002436 -0.018774 0 0 -0 0</pose>
        <mass>0.0458</mass>
        <inertia>
          <ixx>2.29304e-05</ixx>
          <ixy>-4.4183e-06</ixy>
          <ixz>0</ixz>
          <iyy>2.2184e-05</iyy>
          <iyz>0</iyz>
          <izz>4.11145e-05</izz>
        </inertia>
      </inertial>
      <collision name='left_gripper_finger1_knuckle_link_collision'>
        <pose frame=''>0 0 0 0 -0 0</pose>
        <geometry>
          <mesh>
            <scale>1 1 1</scale>
            <uri>file://movo_robotiq/meshes/manipulation/robotiq/collision/robotiq_85_knuckle_link.stl</uri>
          </mesh>
        </geometry>
        <surface>
          <contact>
            <ode>
              <kp>1e+08</kp>
              <kd>1</kd>
            </ode>
          </contact>
          <friction>
            <ode>
              <mu>100000</mu>
              <mu2>100000</mu2>
            </ode>
          </friction>
        </surface>
      </collision>
      <collision name='left_gripper_finger1_knuckle_link_fixed_joint_lump__left_gripper_finger1_finger_link_collision_1'>
        <pose frame=''>-0.004086 -0.031486 0 0 -0 0</pose>
        <geometry>
          <mesh>
            <scale>1 1 1</scale>
            <uri>file://movo_robotiq/meshes/manipulation/robotiq/collision/robotiq_85_finger_link.stl</uri>
          </mesh>
        </geometry>
        <surface>
          <contact>
            <ode>
              <kp>1e+08</kp>
              <kd>1</kd>
            </ode>
          </contact>
          <friction>
            <ode>
              <mu>100000</mu>
              <mu2>100000</mu2>
            </ode>
          </friction>
        </surface>
      </collision>
      <visual name='left_gripper_finger1_knuckle_link_visual'>
        <pose frame=''>0 0 0 0 -0 0</pose>
        <geometry>
          <mesh>
            <scale>1 1 1</scale>
            <uri>file://movo_robotiq/meshes/manipulation/robotiq/visual/robotiq_85_knuckle_link.dae</uri>
          </mesh>
        </geometry>
        <material>
          <script>
            <uri>__default__</uri>
            <name>__default__</name>
          </script>
        </material>
      </visual>
      <visual name='left_gripper_finger1_knuckle_link_fixed_joint_lump__left_gripper_finger1_finger_link_visual_1'>
        <pose frame=''>-0.004086 -0.031486 0 0 -0 0</pose>
        <geometry>
          <mesh>
            <scale>1 1 1</scale>
            <uri>file://movo_robotiq/meshes/manipulation/robotiq/visual/robotiq_85_finger_link.dae</uri>
          </mesh>
        </geometry>
        <material>
          <script>
            <uri>__default__</uri>
            <name>__default__</name>
          </script>
        </material>
      </visual>
      <velocity_decay/>
      <gravity>1</gravity>
      <velocity_decay/>
    </link>
    <joint name='left_gripper_finger1_joint' type='revolute'>
      <child>left_gripper_finger1_knuckle_link</child>
      <parent>left_wrist_3_link</parent>
      <axis>
        <xyz>0 0 1</xyz>
        <limit>
          <lower>0</lower>
          <upper>0.804</upper>
          <effort>1000</effort>
          <velocity>2</velocity>
        </limit>
        <dynamics>
          <spring_reference>0</spring_reference>
          <spring_stiffness>0</spring_stiffness>
        </dynamics>
        <use_parent_model_frame>1</use_parent_model_frame>
      </axis>
    </joint>
    <link name='left_gripper_finger2_inner_knuckle_link'>
      <pose frame=''>1.22176 0.14605 0.76147 3.14159 0 0</pose>
      <inertial>
        <pose frame=''>0 0 0 0 -0 0</pose>
        <mass>0.029951</mass>
        <inertia>
          <ixx>3.9e-05</ixx>
          <ixy>0</ixy>
          <ixz>0</ixz>
          <iyy>5e-06</iyy>
          <iyz>0</iyz>
          <izz>3.5e-05</izz>
        </inertia>
      </inertial>
      <collision name='left_gripper_finger2_inner_knuckle_link_collision'>
        <pose frame=''>0 0 0 0 -0 0</pose>
        <geometry>
          <mesh>
            <scale>1 1 1</scale>
            <uri>file://movo_robotiq/meshes/manipulation/robotiq/collision/robotiq_85_inner_knuckle_link.stl</uri>
          </mesh>
        </geometry>
        <surface>
          <contact>
            <ode>
              <kp>1e+08</kp>
              <kd>1</kd>
            </ode>
          </contact>
          <friction>
            <ode>
              <mu>100000</mu>
              <mu2>100000</mu2>
            </ode>
          </friction>
        </surface>
      </collision>
      <visual name='left_gripper_finger2_inner_knuckle_link_visual'>
        <pose frame=''>0 0 0 0 -0 0</pose>
        <geometry>
          <mesh>
            <scale>1 1 1</scale>
            <uri>file://movo_robotiq/meshes/manipulation/robotiq/visual/robotiq_85_inner_knuckle_link.dae</uri>
          </mesh>
        </geometry>
        <material>
          <script>
            <uri>__default__</uri>
            <name>__default__</name>
          </script>
        </material>
      </visual>
      <gravity>1</gravity>
      <velocity_decay/>
    </link>
    <joint name='left_gripper_finger2_inner_knuckle_joint' type='revolute'>
      <child>left_gripper_finger2_inner_knuckle_link</child>
      <parent>left_wrist_3_link</parent>
      <axis>
        <xyz>-0 -0 -1</xyz>
        <limit>
          <lower>-1e+16</lower>
          <upper>1e+16</upper>
        </limit>
        <dynamics>
          <spring_reference>0</spring_reference>
          <spring_stiffness>0</spring_stiffness>
        </dynamics>
        <use_parent_model_frame>1</use_parent_model_frame>
      </axis>
    </joint>
    <link name='left_gripper_finger2_finger_tip_link'>
      <pose frame=''>1.2648 0.183649 0.76147 3.14159 0 0</pose>
      <inertial>
        <pose frame=''>0 0 0 0 -0 0</pose>
        <mass>0.019555</mass>
        <inertia>
          <ixx>2e-06</ixx>
          <ixy>0</ixy>
          <ixz>0</ixz>
          <iyy>5e-06</iyy>
          <iyz>0</iyz>
          <izz>6e-06</izz>
        </inertia>
      </inertial>
      <collision name='left_gripper_finger2_finger_tip_link_collision'>
        <pose frame=''>0 0 0 0 -0 0</pose>
        <geometry>
          <mesh>
            <scale>1 1 1</scale>
            <uri>file://movo_robotiq/meshes/manipulation/robotiq/collision/robotiq_85_finger_tip_link.stl</uri>
          </mesh>
        </geometry>
        <surface>
          <contact>
            <ode>
              <kp>1e+08</kp>
              <kd>1</kd>
            </ode>
          </contact>
          <friction>
            <ode>
              <mu>100000</mu>
              <mu2>100000</mu2>
            </ode>
          </friction>
        </surface>
      </collision>
      <visual name='left_gripper_finger2_finger_tip_link_visual'>
        <pose frame=''>0 0 0 0 -0 0</pose>
        <geometry>
          <mesh>
            <scale>1 1 1</scale>
            <uri>file://movo_robotiq/meshes/manipulation/robotiq/visual/robotiq_85_finger_tip_link.dae</uri>
          </mesh>
        </geometry>
        <material>
          <script>
            <uri>__default__</uri>
            <name>__default__</name>
          </script>
        </material>
      </visual>
      <gravity>1</gravity>
      <velocity_decay/>
    </link>
    <joint name='left_gripper_finger2_finger_tip_joint' type='revolute'>
      <child>left_gripper_finger2_finger_tip_link</child>
      <parent>left_gripper_finger2_inner_knuckle_link</parent>
      <axis>
        <xyz>-0 -0 -1</xyz>
        <limit>
          <lower>-1e+16</lower>
          <upper>1e+16</upper>
        </limit>
        <dynamics>
          <spring_reference>0</spring_reference>
          <spring_stiffness>0</spring_stiffness>
        </dynamics>
        <use_parent_model_frame>1</use_parent_model_frame>
      </axis>
    </joint>
    <link name='left_gripper_finger2_knuckle_link'>
      <pose frame=''>1.21525 0.163951 0.76147 3.14159 0 0</pose>
      <inertial>
        <pose frame=''>-0.002436 -0.018774 0 0 -0 0</pose>
        <mass>0.0458</mass>
        <inertia>
          <ixx>2.29304e-05</ixx>
          <ixy>-4.4183e-06</ixy>
          <ixz>0</ixz>
          <iyy>2.2184e-05</iyy>
          <iyz>0</iyz>
          <izz>4.11145e-05</izz>
        </inertia>
      </inertial>
      <collision name='left_gripper_finger2_knuckle_link_collision'>
        <pose frame=''>0 0 0 0 -0 0</pose>
        <geometry>
          <mesh>
            <scale>1 1 1</scale>
            <uri>file://movo_robotiq/meshes/manipulation/robotiq/collision/robotiq_85_knuckle_link.stl</uri>
          </mesh>
        </geometry>
        <surface>
          <contact>
            <ode>
              <kp>1e+08</kp>
              <kd>1</kd>
            </ode>
          </contact>
          <friction>
            <ode>
              <mu>100000</mu>
              <mu2>100000</mu2>
            </ode>
          </friction>
        </surface>
      </collision>
      <collision name='left_gripper_finger2_knuckle_link_fixed_joint_lump__left_gripper_finger2_finger_link_collision_1'>
        <pose frame=''>-0.004086 -0.031486 0 0 -0 0</pose>
        <geometry>
          <mesh>
            <scale>1 1 1</scale>
            <uri>file://movo_robotiq/meshes/manipulation/robotiq/collision/robotiq_85_finger_link.stl</uri>
          </mesh>
        </geometry>
        <surface>
          <contact>
            <ode>
              <kp>1e+08</kp>
              <kd>1</kd>
            </ode>
          </contact>
          <friction>
            <ode>
              <mu>100000</mu>
              <mu2>100000</mu2>
            </ode>
          </friction>
        </surface>
      </collision>
      <visual name='left_gripper_finger2_knuckle_link_visual'>
        <pose frame=''>0 0 0 0 -0 0</pose>
        <geometry>
          <mesh>
            <scale>1 1 1</scale>
            <uri>file://movo_robotiq/meshes/manipulation/robotiq/visual/robotiq_85_knuckle_link.dae</uri>
          </mesh>
        </geometry>
        <material>
          <script>
            <uri>__default__</uri>
            <name>__default__</name>
          </script>
        </material>
      </visual>
      <visual name='left_gripper_finger2_knuckle_link_fixed_joint_lump__left_gripper_finger2_finger_link_visual_1'>
        <pose frame=''>-0.004086 -0.031486 0 0 -0 0</pose>
        <geometry>
          <mesh>
            <scale>1 1 1</scale>
            <uri>file://movo_robotiq/meshes/manipulation/robotiq/visual/robotiq_85_finger_link.dae</uri>
          </mesh>
        </geometry>
        <material>
          <script>
            <uri>__default__</uri>
            <name>__default__</name>
          </script>
        </material>
      </visual>
      <velocity_decay/>
      <gravity>1</gravity>
      <velocity_decay/>
    </link>
    <joint name='left_gripper_finger2_joint' type='revolute'>
      <child>left_gripper_finger2_knuckle_link</child>
      <parent>left_wrist_3_link</parent>
      <axis>
        <xyz>-0 -0 -1</xyz>
        <limit>
          <lower>-3.14</lower>
          <upper>3.14</upper>
          <effort>1000</effort>
          <velocity>100</velocity>
        </limit>
        <dynamics>
          <spring_reference>0</spring_reference>
          <spring_stiffness>0</spring_stiffness>
        </dynamics>
        <use_parent_model_frame>1</use_parent_model_frame>
      </axis>
    </joint>
    <link name='left_ee_link'>
      <!--pose frame=''>1.25929 0.13335 0.76147 3.14 -1.57 0</pose-->
      <pose frame=''>1.25929 0.13335 0.76147 3.141592 -1.5707963 0</pose>
      <inertial>
        <pose frame=''>7e-06 -0.005175 -0.06728 0 0 0</pose>
        <mass>0.799312</mass>
        <inertia>
          <ixx>0.00079</ixx>
          <ixy>0</ixy>
          <ixz>4e-06</ixz>
          <iyy>0.00065</iyy>
          <iyz>3e-06</iyz>
          <izz>0.000823</izz>
        </inertia>
      </inertial>
      <collision name='left_ee_link_collision'>
        <pose frame=''>0 0 0 0 -0 0</pose>
        <geometry>
          <sphere>
            <radius>0.01</radius>
          </sphere>
        </geometry>
      </collision>
      <visual name='left_ee_link_visual'>
        <pose frame=''>0 0 0 0 -0 0</pose>
        <geometry>
          <sphere>
            <radius>0.01</radius>
          </sphere>
        </geometry>
      </visual>
    </link>
    <joint name='left_ee_joint' type='fixed'>
      <child>left_ee_link</child>
      <parent>left_wrist_3_link</parent>      
    </joint>    
    <link name='pan_link'>
      <pose frame=''>0.27449 0 0.870315 3.14159 -0 0</pose>
      <inertial>
        <pose frame=''>-3.6e-05 0.021015 -0.052191 0 -0 0</pose>
        <mass>0.470548</mass>
        <inertia>
          <ixx>0.000957</ixx>
          <ixy>0</ixy>
          <ixz>0</ixz>
          <iyy>0.000805</iyy>
          <iyz>-0.000328</iyz>
          <izz>0.000353</izz>
        </inertia>
      </inertial>
      <!--collision name='pan_link_collision'>
        <pose frame=''>0 0 0 0 -0 0</pose>
        <geometry>
          <mesh>
            <scale>1 1 1</scale>
            <uri>file://movo_robotiq/meshes/pan_tilt/collision/pan_link.stl</uri>
          </mesh>
        </geometry>
      </collision-->
      <visual name='pan_link_visual'>
        <pose frame=''>0 0 0 0 -0 0</pose>
        <geometry>
          <mesh>
            <scale>1 1 1</scale>
            <uri>file://movo_robotiq/meshes/pan_tilt/visual/pan_link.dae</uri>
          </mesh>
        </geometry>
      </visual>
    </link>
    <joint name='pan_joint' type='revolute'>
      <child>pan_link</child>
      <parent>linear_actuator_link</parent>
      <axis>
        <xyz>0 -3e-06 -1</xyz>
        <limit>
          <lower>-1.5708</lower>
          <upper>1.5708</upper>
          <effort>7</effort>
          <velocity>0.907571</velocity>
        </limit>
        <dynamics>
          <spring_reference>0</spring_reference>
          <spring_stiffness>0</spring_stiffness>
        </dynamics>
        <use_parent_model_frame>1</use_parent_model_frame>
      </axis>
    </joint>
    <link name='tilt_link'>
      <pose frame=''>0.27449 -0.026 0.961065 0.463649 -1.57079 1.10715</pose>
      <inertial>
        <pose frame=''>0.013478 -0.00669 -0.040467 0 -0 0</pose>
        <mass>1.83451</mass>
        <inertia>
          <ixx>0.00777963</ixx>
          <ixy>-5.63296e-05</ixy>
          <ixz>-0.000358143</ixz>
          <iyy>0.00239627</iyy>
          <iyz>-0.00019448</iyz>
          <izz>0.00257745</izz>
        </inertia>
      </inertial>
      <!--collision name='tilt_link_collision'>
        <pose frame=''>0 0 0 0 -0 0</pose>
        <geometry>
          <mesh>
            <scale>1 1 1</scale>
            <uri>file://movo_robotiq/meshes/pan_tilt/collision/tilt_link.stl</uri>
          </mesh>
        </geometry>
      </collision>
      <collision name='tilt_link_fixed_joint_lump__kinect2_link_collision_1'>
        <pose frame=''>0.05825 -0.010588 -0.026 -1.57079 -0 -1.57079</pose>
        <geometry>
          <mesh>
            <scale>1 1 1</scale>
            <uri>file://movo_robotiq/meshes/sensors/collision/kinect_one_collision.stl</uri>
          </mesh>
        </geometry>
      </collision-->
      <visual name='tilt_link_visual'>
        <pose frame=''>0 0 0 0 -0 0</pose>
        <geometry>
          <mesh>
            <scale>1 1 1</scale>
            <uri>file://movo_robotiq/meshes/pan_tilt/visual/tilt_link.dae</uri>
          </mesh>
        </geometry>
      </visual>
      <visual name='tilt_link_fixed_joint_lump__kinect2_link_visual_1'>
        <pose frame=''>0.05825 -0.010588 -0.026 -1.57079 -0 -1.57079</pose>
        <geometry>
          <mesh>
            <scale>1 1 1</scale>
            <uri>file://movo_robotiq/meshes/sensors/visual/kinect_one.dae</uri>
          </mesh>
        </geometry>
      </visual>
      <gravity>1</gravity>           
    </link>
    <joint name='tilt_joint' type='revolute'>
      <child>tilt_link</child>
      <parent>pan_link</parent>
      <axis>
        <xyz>1e-06 -1 3e-06</xyz>
        <limit>
          <lower>-1.5708</lower>
          <upper>1.5708</upper>
          <effort>7</effort>
          <velocity>0.907571</velocity>
        </limit>
        <dynamics>
          <spring_reference>0</spring_reference>
          <spring_stiffness>0</spring_stiffness>
        </dynamics>
        <use_parent_model_frame>1</use_parent_model_frame>
      </axis>
    </joint>
    <link name='helper_link'>
      <pose frame=''>0.5 0 0 1.5708 3.14159 1.5708</pose>
      <inertial>
        <pose frame=''>0.0 0.0 0.0 0 0 0</pose>
        <mass>60.165</mass>
        <inertia>
          <ixx>3.62586</ixx>
          <ixy>-0.0034936</ixy>
          <ixz>-0.0758314</ixz>
          <iyy>3.63679</iyy>
          <iyz>-0.0727875</iyz>
          <izz>0.107862</izz>
        </inertia>
      </inertial>
      <!--collision name='left_ee_link_collision'>
        <pose frame=''>0 0 0 0 -0 0</pose>
        <geometry>
          <sphere>
            <radius>0.01</radius>
          </sphere>
        </geometry>
      </collision-->
      <visual name='left_ee_link_visual'>
        <pose frame=''>0 0 0 0 -0 0</pose>
        <geometry>
          <sphere>
            <radius>0.01</radius>
          </sphere>
        </geometry>
      </visual>
    </link>
    <joint name='helper_joint' type='fixed'>
      <child>helper_link</child>
      <parent>base_link</parent>      
    </joint>     
    <static>0</static>    
  </model>
</sdf>
